<?xml version='1.0'?>

<robot name="myrobot" xmlns:xacro="http://www.ros.org/wiki/xacro">

  <xacro:include filename="$(find rsk_bot)/urdf/stereo_bot/stereo_bot.gazebo.xacro" />
  <xacro:include filename="$(find rsk_bot)/urdf/common_properties.xacro" />

  <xacro:property name="chassis_x" value="0.4"/>
  <xacro:property name="chassis_y" value="0.2"/>
  <xacro:property name="chassis_z" value="0.1"/>
  <xacro:property name="chassis_mass" value="10"/>

  <xacro:property name="wheel_length" value="0.05"/>
  <xacro:property name="wheel_radius" value="0.1"/>
  <xacro:property name="wheel_mass" value="5"/>

  <xacro:property name="cameraRadius" value="0.02"/>
  <xacro:property name="cameraLength" value="0.05"/>
  <xacro:property name="cameraMass" value="0.1"/>

  <!-- ######################################################################################################################## -->

  <link name="base_footprint"/>

  <!-- ######################################################################################################################## -->

  <joint name="base_joint" type="fixed">
    <parent link="base_footprint"/>
    <child link="base_link"/>
    <origin xyz="0.0 0.0 0.010" rpy="0 0 0"/>
  </joint>

  <link name='base_link'>

    <visual>
      <origin xyz="0 0 0" rpy=" 0 0 0"/>
      <geometry>
        <box size="${chassis_x} ${chassis_y} ${chassis_z}"/>
      </geometry>
    </visual>

    <collision>
      <geometry>
        <box size="${chassis_x} ${chassis_y} ${chassis_z}"/>
      </geometry>
    </collision>

    <inertial>
      <origin xyz="0 0 0.1" rpy=" 0 0 0"/>
      <mass value="${chassis_mass}"/>
      <inertia ixx="${0.0833333 * chassis_mass * (chassis_y*chassis_y + chassis_z*chassis_z)}" ixy="0.0" ixz="0.0"
        iyy="${0.0833333 * chassis_mass * (chassis_x*chassis_x + chassis_z*chassis_z)}" iyz="0.0"
        izz="${0.0833333 * chassis_mass * (chassis_x*chassis_x + chassis_y*chassis_y)}" />
    </inertial>  
 
  </link>

  <!-- ######################################################################################################################## -->

  <joint name="caster_joint" type="fixed">
    <parent link="base_link"/>
    <child link="caster_link"/>
    <origin xyz="-0.15 0 -0.05" rpy="0 0 0"/>
  </joint>

  <link name='caster_link'>

    <visual>
      <origin xyz="0 0 0" rpy=" 0 0 0"/>
      <geometry>
        <sphere radius="0.05"/>
      </geometry>
    </visual>

    <collision>
      <origin xyz="0 0 0" rpy=" 0 0 0"/>
      <geometry>
        <sphere radius="0.05"/>
      </geometry>
      <surface>   <!--Defines the surface property-->
        <friction>
          <ode>
            <mu>0</mu>
            <mu2>0</mu2>
            <slip1>1.0</slip1>
            <slip2>1.0</slip2>
          </ode>
        </friction>
      </surface>
    </collision>

  </link>

  <!-- ######################################################################################################################## -->

  <joint type="continuous" name="wheel_left_joint">
    <origin xyz="0.1 0.15 0" rpy="0 0 0"/>
    <child link="left_wheel"/>
    <parent link="base_link"/>
    <axis xyz="0 1 0" rpy="0 0 0"/>
    <limit effort="100" velocity="100"/>
    <joint_properties damping="0.0" friction="0.0"/>
  </joint>

  <link name="left_wheel">
    <!--origin xyz="0.1 0.13 0.1" rpy="0 1.5707 1.5707"/-->
    <visual name="left_wheel_visual">
      <origin xyz="0 0 0" rpy="0 1.5707 1.5707"/>
      <geometry>
        <cylinder radius="${wheel_radius}" length="${wheel_length}"/>
      </geometry>
    </visual>

    <collision name="collision">
      <origin xyz="0 0 0" rpy="0 1.5707 1.5707"/>
      <geometry>
        <cylinder radius="${wheel_radius}" length="${wheel_length}"/>
      </geometry>
    </collision>
    
    <inertial>
      <origin xyz="0 0 0" rpy="0 1.5707 1.5707"/>
      <mass value="${wheel_mass}"/>
      <cylinder_inertia m="${wheel_mass}" r="${wheel_radius}" h="${wheel_length}"/>
      <inertia ixx="${0.0833333 * wheel_mass * (3 * wheel_radius * wheel_radius + wheel_length * wheel_length)}" ixy="0.0" ixz="0.0"
        iyy="${0.0833333 * wheel_mass * (3 * wheel_radius * wheel_radius + wheel_length * wheel_length)}" iyz="0.0"
        izz="${0.5 * wheel_mass * wheel_radius * wheel_radius}" />
    </inertial>
  </link>

  <!-- ######################################################################################################################## -->

  <joint type="continuous" name="wheel_right_joint">
    <origin xyz="0.1 -0.15 0" rpy="0 0 0"/>
    <child link="right_wheel"/>
    <parent link="base_link"/>
    <axis xyz="0 1 0" rpy="0 0 0"/>
    <limit effort="100" velocity="100"/>
    <joint_properties damping="0.0" friction="0.0"/>
  </joint>

  <link name="right_wheel">
    <!--origin xyz="0.1 -0.13 0.1" rpy="0 1.5707 1.5707"/-->
    <visual name="right_wheel_visual">
      <origin xyz="0 0 0" rpy="0 1.5707 1.5707"/>
      <geometry>
        <cylinder radius="${wheel_radius}" length="${wheel_length}"/>
      </geometry>
    </visual>

    <collision name="collision">
      <origin xyz="0 0 0" rpy="0 1.5707 1.5707"/>
      <geometry>
        <cylinder radius="${wheel_radius}" length="${wheel_length}"/>
      </geometry>
    </collision>

    <inertial>
      <origin xyz="0 0 0" rpy="0 1.5707 1.5707"/>
      <mass value="5"/>
      <cylinder_inertia m="${wheel_mass}" r="${wheel_radius}" h="${wheel_length}"/>
      <inertia ixx="${0.0833333 * wheel_mass * (3 * wheel_radius * wheel_radius + wheel_length * wheel_length)}" ixy="0.0" ixz="0.0"
        iyy="${0.0833333 * wheel_mass * (3 * wheel_radius * wheel_radius + wheel_length * wheel_length)}" iyz="0.0"
        izz="${0.5 * wheel_mass * wheel_radius * wheel_radius}" />
    </inertial>
  </link>

  <!-- ######################################################################################################################## -->

  <joint name="stereo_camera_joint" type="fixed">
    <origin xyz="0.15 0.055 0.15" rpy="0 0 0"/>
    <parent link="base_link"/>
    <child link="stereo_camera_link"/>
  </joint>

  <link name="stereo_camera_link">

    <visual>
      <origin xyz="0 0 0" rpy="0 ${pi/2} 0"/>
      <geometry>
        <cylinder radius="${cameraRadius}" length="${cameraLength}"/>
      </geometry>
      <material name="green"/>
    </visual>

    <collision>
      <origin xyz="0 0 0" rpy="0 ${-pi/2} 0"/>
      <geometry>
        <cylinder radius="${cameraRadius}" length="${cameraLength}"/>
      </geometry>
    </collision>
    
    <inertial>
      <mass value="${cameraMass}" />
      <origin xyz="0 0 0" rpy="0 ${-pi/2} 0"/>
      <inertia ixx="1e-6" ixy="0" ixz="0" iyy="1e-6" iyz="0" izz="1e-6" />
    </inertial>

  </link>

	
  <!-- ######################################################################################################################## -->

   <joint name="stereo_camera_optical_joint" type="fixed">
    <origin xyz="0 0 0" rpy="${-pi/2} 0 ${-pi/2}"/>
    <parent link="stereo_camera_link"/>
    <child link="stereo_camera_optical_link"/>
  </joint>

  <link name="stereo_camera_optical_link"/>

  <!-- ######################################################################################################################## -->

</robot>
